<?xml version="1.0"?>
<robot name="Bionico Hand" xmlns:xacro="http://www.ros.org/wiki/xacro" >

<!-- GLOBAL Variable -->
<xacro:property name="degToRad" value="${pi/180}" />
<xacro:property name="PI_2" value="${pi/2}" />

<!-- INDEX Position and Length-->
<xacro:property name="Index_Proximal_Lenght" value="44" />
<xacro:property name="Index_Middle_Lenght" value="28" />
<xacro:property name="IndexMcp_origin">
  <origin xyz="86 23 -4" rpy="${-2.5*degToRad} 0 ${3.0*degToRad}" />
</xacro:property>
<xacro:property name="IndexPip_origin">
  <origin xyz="${Index_Proximal_Lenght} 0 0" rpy="0 0 0" />
</xacro:property>
<xacro:property name="IndexDip_origin">
  <origin xyz="${Index_Middle_Lenght} 0 0" rpy="0 0 0" />
</xacro:property>

<!-- MIDDLE Position and Length-->
<xacro:property name="Middle_Proximal_Lenght" value="47" />
<xacro:property name="Middle_Middle_Lenght" value="32" />
<xacro:property name="MiddleMcp_origin">
  <origin xyz="89 0 0" rpy="0 0 0" />
</xacro:property>
<xacro:property name="MiddlePip_origin">
  <origin xyz="${Middle_Proximal_Lenght} 0 0" rpy="0 0 0" />
</xacro:property>
<xacro:property name="MiddleDip_origin">
  <origin xyz="${Middle_Middle_Lenght} 0 0" rpy="0 0 0" />
</xacro:property>

<!-- RING Position and Length-->
<xacro:property name="Ring_Proximal_Lenght" value="44" />
<xacro:property name="Ring_Middle_Lenght" value="28" />
<xacro:property name="RingMcp_origin">
  <origin xyz="88 -23 -6" rpy="${2.5*degToRad} 0 ${-3.0*degToRad}" />
</xacro:property>
<xacro:property name="RingPip_origin">
  <origin xyz="${Ring_Proximal_Lenght} 0 0" rpy="0 0 0" />
</xacro:property>
<xacro:property name="RingDip_origin">
  <origin xyz="${Ring_Middle_Lenght} 0 0" rpy="0 0 0" />
</xacro:property>

<!-- PINKY Position and Length-->
<xacro:property name="Pinky_Proximal_Lenght" value="38" />
<xacro:property name="Pinky_Middle_Lenght" value="25" />
<xacro:property name="PinkyMcp_origin">
  <origin xyz="78 -43 -9" rpy="${4.5*degToRad} 0 ${-6.0*degToRad}" />
</xacro:property>
<xacro:property name="PinkyPip_origin">
  <origin xyz="${Pinky_Proximal_Lenght} 0 0" rpy="0 0 0" />
</xacro:property>
<xacro:property name="PinkyDip_origin">
  <origin xyz="${Pinky_Middle_Lenght} 0 0" rpy="0 0 0" />
</xacro:property>

<!-- THUMB Position and Length-->
<xacro:property name="Thumb_Carpal_Lenght" value="10" />
<xacro:property name="Thumb_MetaCarpal_Lenght" value="35" />
<xacro:property name="Thumb_Proximal_Lenght" value="38" />

<!-- COLOR -->
  <material name="white">
    <color rgba="1 1 1 1"/>
  </material>

<!-- FINGER LINK Macro-->
<xacro:macro name="finger_link" params="fingerName">
  <link name="${fingerName}_Proximal">
    <visual>
      <origin xyz="0 0 0" rpy="${PI_2} 0 0" />
      <geometry>
        <mesh filename="package://hand_description/meshes/MHK_01_${fingerName}_Proximal.STL" scale="1.0 1.0 1.0"/>
      </geometry>
      <material name="white"/>
    </visual>
  </link>

  <link name="${fingerName}_Middle">
    <visual>
      <origin xyz="0 0 0" rpy="${PI_2} 0 0" />
      <geometry>
        <mesh filename="package://hand_description/meshes/MHK_01_${fingerName}_Middle.STL" scale="1.0 1.0 1.0"/>
      </geometry>
      <material name="white"/>
    </visual>
  </link>

  <link name="${fingerName}_Distal">
    <visual>
      <origin xyz="0 0 0" rpy="${PI_2} 0 0" />
      <geometry>
        <mesh filename="package://hand_description/meshes/MHK_01_${fingerName}_Distal.STL" scale="1.0 1.0 1.0"/>
      </geometry>
      <material name="white"/>
    </visual>
  </link>
</xacro:macro>

<!-- FINGER JOINT Macro-->
<xacro:macro name="finger_joint" params="fingerName *origin_Mcp *origin_Pip *origin_Dip">
  <joint name="${fingerName}Mcp" type="continuous">
    <parent link="palm"/>
    <child link="${fingerName}_Proximal"/>
    <xacro:insert_block name="origin_Mcp" />
    <axis xyz="0.0 1.0 0.0" />
  </joint>

  <joint name="${fingerName}Pip" type="continuous">
    <parent link="${fingerName}_Proximal"/>
    <child link="${fingerName}_Middle"/>
    <xacro:insert_block name="origin_Pip" />
    <axis xyz="0.0 1.0 0.0" />
  </joint>

  <joint name="${fingerName}Dip" type="continuous">
    <parent link="${fingerName}_Middle"/>
    <child link="${fingerName}_Distal"/>
    <xacro:insert_block name="origin_Dip" />
    <axis xyz="0.0 1.0 0.0" />
  </joint>
</xacro:macro>

<!-- PALM LINK-->
  <link name="palm">
    <visual>
      <origin xyz="0 0 0" rpy="0 0 0" />
      <geometry>
        <mesh filename="package://hand_description/meshes/MHK_01_Palm.STL" scale="1.0 1.0 1.0"/>
      </geometry>
      <material name="white"/>
    </visual>
  </link>

<!-- FINGER LINK-->
  <xacro:finger_link fingerName="Index"/>
  <xacro:finger_link fingerName="Middle"/>
  <xacro:finger_link fingerName="Ring"/>
  <xacro:finger_link fingerName="Pinky"/>
  
<!-- FINGER JOINTS-->
  <xacro:finger_joint fingerName="Index">
    <xacro:insert_block name="IndexMcp_origin" />
    <xacro:insert_block name="IndexPip_origin" />
    <xacro:insert_block name="IndexDip_origin" />
  </xacro:finger_joint>

  <xacro:finger_joint fingerName="Middle">
    <xacro:insert_block name="MiddleMcp_origin" />
    <xacro:insert_block name="MiddlePip_origin" />
    <xacro:insert_block name="MiddleDip_origin" />
  </xacro:finger_joint>

  <xacro:finger_joint fingerName="Ring">
    <xacro:insert_block name="RingMcp_origin" />
    <xacro:insert_block name="RingPip_origin" />
    <xacro:insert_block name="RingDip_origin" />
  </xacro:finger_joint>

  <xacro:finger_joint fingerName="Pinky">
    <xacro:insert_block name="PinkyMcp_origin" />
    <xacro:insert_block name="PinkyPip_origin" />
    <xacro:insert_block name="PinkyDip_origin" />
  </xacro:finger_joint>

<!-- THUMB LINK -->
  <link name="Thumb_Carpal">
    <visual>
      <origin xyz="0 0 0" rpy="0 0 0" />
      <geometry>
        <sphere radius="3"/>
      </geometry>
    </visual>
  </link>

  <link name="Thumb_MetaCarpal">
    <visual>
      <origin xyz="0 0 0" rpy="0 ${PI_2} 0" />
      <geometry>
        <mesh filename="package://hand_description/meshes/MHK_01_Thumb_MetaCarpal.STL" scale="1.0 1.0 1.0"/>
      </geometry>
      <material name="white"/>
    </visual>
  </link>

  <link name="Thumb_Proximal">
    <visual>
      <origin xyz="0 0 0" rpy="0 ${PI_2} 0" />
      <geometry>
        <mesh filename="package://hand_description/meshes/MHK_01_Thumb_Proximal.STL" scale="1.0 1.0 1.0"/>
      </geometry>
      <material name="white"/>
    </visual>
  </link>

  <link name="Thumb_Distal">
    <visual>
      <origin xyz="0 0 0" rpy="0 ${PI_2} 0" />
      <geometry>
        <mesh filename="package://hand_description/meshes/MHK_01_Thumb_Distal.STL" scale="1.0 1.0 1.0"/>
      </geometry>
      <material name="white"/>
    </visual>
  </link>

<!-- THUMB JOINT -->
  <joint name="ThumbCarpal" type="continuous">
    <parent link="palm"/>
    <child link="Thumb_Carpal"/>
    <origin xyz="26 10 -26" rpy="0 0 ${165.0*degToRad}" />
    <axis xyz="1.0 0.0 0.0" />
  </joint>

  <joint name="ThumbMcp" type="continuous">
    <parent link="Thumb_Carpal"/>
    <child link="Thumb_MetaCarpal"/>
    <origin xyz="0 0 -${Thumb_Carpal_Lenght}" rpy="0 0 0" />
    <axis xyz="0.0 1.0 0.0" />
  </joint>

  <joint name="ThumbPip" type="continuous">
    <parent link="Thumb_MetaCarpal"/>
    <child link="Thumb_Proximal"/>
    <origin xyz="0 0 -${Thumb_MetaCarpal_Lenght}" rpy="0 0 0" />
    <axis xyz="0.0 1.0 0.0" />
  </joint>

  <joint name="ThumbDip" type="continuous">
    <parent link="Thumb_Proximal"/>
    <child link="Thumb_Distal"/>
    <origin xyz="0 0 -${Thumb_Proximal_Lenght}" rpy="0 0 0" />
    <axis xyz="0.0 1.0 0.0" />
  </joint>


</robot>

